Traceback (most recent call last):
  File "C:\Program Files\WindowsApps\PythonSoftwareFoundation.Python.3.12_3.12.1264.0_x64__qbz5n2kfra8p0\Lib\tkinter\__init__.py", line 1968, in __call__
    return self.func(*args)
           ^^^^^^^^^^^^^^^^
  File "C:\Users\Antonio\Documents\GitHub\SDI_Tools\SpecTool.py", line 1016, in <lambda>
    modify = tk.Button(root, text = "Modify Entry", command=lambda:ModifyEntry(con, treeview, root, messageBox))
                                                                   ^^^^^^^^^^^^^^^^^^^^^^^^^^^^^^^^^^^^^^^^^^^^
  File "C:\Users\Antonio\Documents\GitHub\SDI_Tools\SpecTool.py", line 826, in ModifyEntry
    msg.config(text="Couldn\'t update entry")
  File "C:\Program Files\WindowsApps\PythonSoftwareFoundation.Python.3.12_3.12.1264.0_x64__qbz5n2kfra8p0\Lib\tkinter\__init__.py", line 1722, in configure
    return self._configure('configure', cnf, kw)
           ^^^^^^^^^^^^^^^^^^^^^^^^^^^^^^^^^^^^^
  File "C:\Program Files\WindowsApps\PythonSoftwareFoundation.Python.3.12_3.12.1264.0_x64__qbz5n2kfra8p0\Lib\tkinter\__init__.py", line 1712, in _configure
    self.tk.call(_flatten((self._w, cmd)) + self._options(cnf))
_tkinter.TclError: invalid command name ".!label"

During handling of the above exception, another exception occurred:

Traceback (most recent call last):
  File "C:\Users\Antonio\Documents\GitHub\SDI_Tools\SpecTool.py", line 1135, in <module>
    root.mainloop()
  File "C:\Program Files\WindowsApps\PythonSoftwareFoundation.Python.3.12_3.12.1264.0_x64__qbz5n2kfra8p0\Lib\tkinter\__init__.py", line 1505, in mainloop
    self.tk.mainloop(n)
  File "C:\Program Files\WindowsApps\PythonSoftwareFoundation.Python.3.12_3.12.1264.0_x64__qbz5n2kfra8p0\Lib\tkinter\__init__.py", line 1972, in __call__
    self.widget._report_exception()
  File "C:\Program Files\WindowsApps\PythonSoftwareFoundation.Python.3.12_3.12.1264.0_x64__qbz5n2kfra8p0\Lib\tkinter\__init__.py", line 1688, in _report_exception
    root.report_callback_exception(exc, val, tb)
  File "C:\Users\Antonio\Documents\GitHub\SDI_Tools\SpecTool.py", line 42, in handle_exception
    top=tk.Toplevel(root)
        ^^^^^^^^^^^^^^^^^
  File "C:\Program Files\WindowsApps\PythonSoftwareFoundation.Python.3.12_3.12.1264.0_x64__qbz5n2kfra8p0\Lib\tkinter\__init__.py", line 2708, in __init__
    BaseWidget.__init__(self, master, 'toplevel', cnf, {}, extra)
  File "C:\Program Files\WindowsApps\PythonSoftwareFoundation.Python.3.12_3.12.1264.0_x64__qbz5n2kfra8p0\Lib\tkinter\__init__.py", line 2659, in __init__
    self.tk.call(
_tkinter.TclError: can't invoke "toplevel" command: application has been destroyed
