Traceback (most recent call last):
  File "C:\Users\Antonio\Documents\GitHub\SDI_Tools\BulkLoads.py", line 25, in resource_path
    base_path = sys._MEIPASS
                ^^^^^^^^^^^^
AttributeError: module 'sys' has no attribute '_MEIPASS'

During handling of the above exception, another exception occurred:

Traceback (most recent call last):
  File "C:\Users\Antonio\Documents\GitHub\SDI_Tools\BulkLoads.py", line 64, in <module>
    ico= Image.open(resource_path("SDI_Logo.ico"))
                    ^^^^^^^^^^^^^^^^^^^^^^^^^^^^^
  File "C:\Users\Antonio\Documents\GitHub\SDI_Tools\BulkLoads.py", line 27, in resource_path
    base_path = os.path.abs("./_internal")
                ^^^^^^^^^^^
AttributeError: module 'ntpath' has no attribute 'abs'
AttributeError: module 'ntpath' has no attribute 'abs'