Traceback (most recent call last):
  File "C:\Users\Antonio\Documents\GitHub\SDI_Tools\SpecTool.py", line 1178, in DBWindow
    con=sqlite3.connect("file:"+dbPath+"?mode=rw", uri=True)
        ^^^^^^^^^^^^^^^^^^^^^^^^^^^^^^^^^^^^^^^^^^^^^^^^^^^^
sqlite3.OperationalError: unable to open database file

During handling of the above exception, another exception occurred:

Traceback (most recent call last):
  File "C:\Program Files\WindowsApps\PythonSoftwareFoundation.Python.3.12_3.12.1264.0_x64__qbz5n2kfra8p0\Lib\tkinter\__init__.py", line 1968, in __call__
    return self.func(*args)
           ^^^^^^^^^^^^^^^^
  File "C:\Users\Antonio\Documents\GitHub\SDI_Tools\SpecTool.py", line 1180, in DBWindow
    con=sqlite3.connect(dbPath)
        ^^^^^^^^^^^^^^^^^^^^^^^
sqlite3.OperationalError: unable to open database file
OperationalError: unable to open database file